<?xml version="1.0" ?>
<robot name="my_hexapod" >

    <!-- Propiedades -->

    <material name="color_base">
        <color rgba="0 0 0.5 1" />
    </material>

    <material name="color_red">
        <color rgba="0.5 0 0 1" />
    </material>

    <material name="color_green">
        <color rgba="0 0.5 0 1" />
    </material>

    <!-- Eslabon Vacío (Para que se mueva)-->
    <link name="base_footprint" />

    <!-- Eslabon Base -->
    <link name="base_link">
        <visual>
            <geometry>
                <box size="0.3 0.2 0.10" />
            </geometry>
            <origin xyz="0.0 0.0 0.0" rpy="0 0 0"/>
            <material name="color_base" />
        </visual>
    </link>

    <!-- Juntas para el movimiento -->

    <!-- Junta entre cuerpo vacío y cuerpo base-->
    <joint name="base_footprint_to_base_link_joint" type="fixed" >
        <parent link="base_footprint" />
        <child link="base_link" />
        <origin xyz="0 0 0.15" rpy="0 0 0" />
    </joint>

    <!-- Eslabones Normales -->
    
    <!-- Eslabón COXA -->
    <link name="coxa_p1_link">
        <visual>
            <geometry>
                <box size="0.05 0.15 0.05" />
            </geometry>
            <origin xyz="0.0 0.075 0" rpy="0 0 0"/>
            <material name="color_red" />
        </visual>
    </link>

    <!-- Eslabón FEMUR-->
    <link name="femur_p1_link">
        <visual>
            <geometry>
                <box size="0.05 0.15 0.05" />
            </geometry>
            <origin xyz="0.0 0.075 0.0" rpy="0 0 0"/>
            <material name="color_green" />
        </visual>
    </link>

    <!-- Eslabón TIBIA -->
    <link name="tibia_p1_link">
        <visual>
            <geometry>
                <box size="0.05 0.15 0.05" />
            </geometry>
            <origin xyz="0.0 0.075 0.0" rpy="0 0 0"/>
            <material name="color_base" />
        </visual>
    </link>

    <!-- Juntas para formar la pata-->

    <!-- Junta entre el cuerpo base y el coxa -->
    <joint name="base_link_to_coxa_p1_link_joint" type="revolute">
        <parent link="base_link" />
        <child link="coxa_p1_link" />
        <origin xyz="0.0 0.1 0.005" rpy="0 0 0" />
        <axis xyz="0 0 1" />
        <limit lower="-1.57" upper="1.57" effort="0.176" velocity="0.166" />
    </joint>

    <!-- Junta entre el coxa y el femur -->
    <joint name="coxa_p1_link_to_femur_p1_link_joint" type="revolute">
        <parent link="coxa_p1_link" />
        <child link="femur_p1_link" />
        <origin xyz="0.0 0.15 0.0" rpy="0 0 0" />
        <axis xyz="1 0 0" />
        <limit lower="-1.57" upper="1.57" effort="0.176" velocity="0.166" />
    </joint>

    <!-- Junta entre el femur y la tibia -->
    <joint name="femur_p1_link_to_tibia_p1_link_joint" type="revolute">
        <parent link="femur_p1_link" />
        <child link="tibia_p1_link" />
        <origin xyz="0.0 0.15 0.0" rpy="0 0 0" />
        <axis xyz="1 0 0" />
        <limit lower="-1.57" upper="1.57" effort="0.176" velocity="0.166" />
    </joint>

</robot>
