<?xml version="1.0"?>
<robot name="hexapod">

    <material name="blue">
        <color rgba="0 0 0.5 1" />
    </material>

    <material name="red">
        <color rgba="0.5 0.0 0.0 1" />
    </material>

    <material name="green">
        <color rgba="0.0 0.5 0.0 1" />
    </material>



    <link name="base_footprint" />

    <link name="base_link">
        <visual>
            <geometry>
                <box size="0.3 0.2 0.10" />
            </geometry>
            <origin xyz="0 0 0" rpy="0 0 0" />
            <material name="blue" />
        </visual>
    </link>


    <joint name="base_footprint_to_base_link_joint" type="fixed">
        <parent link="base_footprint" />
        <child link="base_link" />
        <origin xyz="0.0 0 0.15" rpy="0 0 0" />
    </joint>


    <link name="coxa_link">
        <visual>
            <geometry>
                <box size="0.05 0.15 0.05" />
            </geometry>
            <origin xyz="0 0.075 0" rpy="0 0 0" />
            <material name="red" />
        </visual>
    </link>

    <joint name="base_link_to_coxa_link_joint" type="revolute">
        <parent link="base_link" />
        <child link="coxa_link" />
        <origin xyz="0.0  0.1 0.005" rpy="0 0 0" />
        <axis xyz="0 0 1" />
        <limit lower="-1.57" upper="1.57" 
                effort="0.176" velocity="0.166" />
    </joint>

    <link name="pata1_link">
        <visual>
            <geometry>
                <box size="0.05 0.15 0.05" />
            </geometry>
            <origin xyz="0 0.075 0" rpy="0 0 0" />
            <material name="blue" />
        </visual>
    </link>

    <joint name="coxa_link_to_pata1_link_joint" type="revolute">
        <parent link="coxa_link" />
        <child link="pata1_link" />
        <origin xyz="0.0  0.15 0.0" rpy="0 0 0" />
        <axis xyz="1 0 0" />
        <limit lower="-1.57" upper="1.57" 
                effort="0.176" velocity="0.166" />
    </joint>


    <link name="pata2_link">
        <visual>
            <geometry>
                <box size="0.05 0.15 0.05" />
            </geometry>
            <origin xyz="0 0.075 0" rpy="0 0 0" />
            <material name="green" />
        </visual>
    </link>

    <joint name="pata1_link_to_pata2_link_joint" type="revolute">
        <parent link="pata1_link" />
        <child link="pata2_link" />
        <origin xyz="0.0  0.15 0.0" rpy="0 0 0" />
        <axis xyz="1 0 0" />
        <limit lower="-1.57" upper="1.57" 
                effort="0.176" velocity="0.166" />
    </joint>


</robot>